# Возбуждает указанное исключение.
# Инструкция позволяет прервать штатный поток исполнения при помощи возбуждения исключения.

try:
    print(1 / 0)

except Exception as exc:
    # Наше второе исключение никто не поймает
    # поэтому будет выведена цепочка
    # из двух исключений.
    raise RuntimeError('Явная цепочка исключений') from exc
